["```py\n# custom.py\ndef debug(*msg, print_separator=True):\n    print(*msg)\n    if print_separator:\n        print('-' * 40)\n\ndebug('Data is ...')\ndebug('Different', 'Strings', 'Are not a problem')\ndebug('After while loop', print_separator=False)\n```", "```py\n$ python custom.py\nData is ...\n----------------------------------------\nDifferent Strings Are not a problem\n----------------------------------------\nAfter while loop\n```", "```py\n# custom_timestamp.py\nfrom time import sleep\n\ndef debug(*msg, timestamp=[None]):\n    print(*msg)\n    from time import time  # local import\n    if timestamp[0] is None:\n        timestamp[0] = time()  #1\n    else:\n        now = time()\n        print(\n            ' Time elapsed: {:.3f}s'.format(now - timestamp[0])\n        )\n        timestamp[0] = now  #2\n\ndebug('Entering nasty piece of code...')\nsleep(.3)\ndebug('First step done.')\nsleep(.5)\ndebug('Second step done.')\n```", "```py\n$ python custom_timestamp.py\nEntering nasty piece of code...\nFirst step done.\n Time elapsed: 0.304s\nSecond step done.\n Time elapsed: 0.505s\n```", "```py\n# traceback_simple.py\nd = {'some': 'key'}\nkey = 'some-other'\nprint(d[key])\n```", "```py\n$ python traceback_simple.py\nTraceback (most recent call last):\n File \"traceback_simple.py\", line 3, in <module>\n print(d[key])\nKeyError: 'some-other'\n```", "```py\n# traceback_validator.py\nclass ValidatorError(Exception):\n    \"\"\"Raised when accessing a dict results in KeyError. \"\"\"\n\nd = {'some': 'key'}\nmandatory_key = 'some-other'\ntry:\n    print(d[mandatory_key])\nexcept KeyError as err:\n    raise ValidatorError(\n        f'`{mandatory_key}` not found in d.'\n    ) from err\n```", "```py\n$ python traceback_validator.py\nTraceback (most recent call last):\n File \"traceback_validator.py\", line 7, in <module>\n print(d[mandatory_key])\nKeyError: 'some-other'\n\nThe above exception was the direct cause of the following exception:\n\nTraceback (most recent call last):\n File \"traceback_validator.py\", line 10, in <module>\n '`{}` not found in d.'.format(mandatory_key)) from err\n__main__.ValidatorError: `some-other` not found in d.\n```", "```py\n# pdebugger.py\n# d comes from a JSON payload we don't control\nd = {'first': 'v1', 'second': 'v2', 'fourth': 'v4'}\n# keys also comes from a JSON payload we don't control\nkeys = ('first', 'second', 'third', 'fourth')\n\ndef do_something_with_value(value):\n    print(value)\n\nfor key in keys:\n    do_something_with_value(d[key])\n\nprint('Validation done.')\n```", "```py\n$ python pdebugger.py\nv1\nv2\nTraceback (most recent call last):\n File \"pdebugger.py\", line 10, in <module>\n do_something_with_value(d[key])\nKeyError: 'third'\n```", "```py\nimport pdb\npdb.set_trace()\n```", "```py\nbreakpoint()\n```", "```py\n$ python pdebugger_pdb.py\n(Pdb++) l\n 16\n 17 -> for key in keys:  # breakpoint comes in\n 18 do_something_with_value(d[key])\n 19\n\n(Pdb++) keys  # inspecting the keys tuple\n('first', 'second', 'third', 'fourth')\n(Pdb++) d.keys()  # inspecting keys of `d`\ndict_keys(['first', 'second', 'fourth'])\n(Pdb++) d['third'] = 'placeholder'  # add tmp placeholder\n(Pdb++) c  # continue\nv1\nv2\nplaceholder\nv4\nValidation done.\n```", "```py\n# log.py\nimport logging\n\nlogging.basicConfig(\n    filename='ch11.log',\n    level=logging.DEBUG,  # minimum level capture in the file\n    format='[%(asctime)s] %(levelname)s: %(message)s',\n    datefmt='%m/%d/%Y %I:%M:%S %p')\n\nmylist = [1, 2, 3]\nlogging.info('Starting to process `mylist`...')\n\nfor position in range(4):\n    try:\n        logging.debug(\n            'Value at position %s is %s', position, mylist[position]\n        )\n    except IndexError:\n        logging.exception('Faulty position: %s', position)\n\nlogging.info('Done parsing `mylist`.')\n```", "```py\n# ch11.log\n[05/06/2018 11:13:48 AM] INFO:Starting to process `mylist`...\n[05/06/2018 11:13:48 AM] DEBUG:Value at position 0 is 1\n[05/06/2018 11:13:48 AM] DEBUG:Value at position 1 is 2\n[05/06/2018 11:13:48 AM] DEBUG:Value at position 2 is 3\n[05/06/2018 11:13:48 AM] ERROR:Faulty position: 3\nTraceback (most recent call last):\n  File \"log.py\", line 15, in <module>\n    position, mylist[position]))\nIndexError: list index out of range\n[05/06/2018 11:13:48 AM] INFO:Done parsing `mylist`.\n```", "```py\n# assertions.py\nmylist = [1, 2, 3]  # this ideally comes from some place\nassert 4 == len(mylist)  # this will break\nfor position in range(4):\n    print(mylist[position])\n```", "```py\n$ python assertions.py\nTraceback (most recent call last):\n File \"assertions.py\", line 3, in <module>\n assert 4 == len(mylist)  # this will break\nAssertionError\n```"]